Workbook

Sheet General
A1: First | B1: Last | C1: Name | D1: Year | E1: City / State (played for / living) | F1: US Mail Address | G1: Email Address | H1: Work # | I1: FAX | J1: Home # | K1: Spouse
A2: Roger | B2: Aceto (deceased) | C2: =A2&" "&B2 -> Roger Aceto (deceased) | D2: 1982 | E2: Urbandale Ia. 50322 | F2: 4201 82nd Street
A3: Gary | B3: Alberhasky | C3: =A3&" "&B3 -> Gary Alberhasky | D3: 2011 | E3: Iowa City, IA 52240 | F3: 4274 Sioux Ave SE | G3: linalb65@aol.com | J3: 319-354-7128
A4: Ron | B4: Amick | C4: =A4&" "&B4 -> Ron Amick | D4: 1997 | E4: Sioux City, Ia. 51106 | F4: 1516 Old HWY 141 | G4: none
A5: John | B5: Amsbaugh | C5: =A5&" "&B5 -> John Amsbaugh | D5: 2019 | E5: Des Moines, IA 50266 | J5: 515-457-9515
A6: Steve | B6: Anderson | C6: =A6&" "&B6 -> Steve Anderson | D6: 2019 | E6: Cedar Rapids, Ia. 52402
A7: Ev | B7: Andrew (deceased) | C7: =A7&" "&B7 -> Ev Andrew (deceased) | D7: 1983 | E7: Mount Vernon, IA ***Deceased***
A8: Steve | B8: Andrew (deceased) | C8: =A8&" "&B8 -> Steve Andrew (deceased) | D8: 1993 | E8: Cedar Rapids, Ia. 52402-2328 | F8: 2180 David Ct. NE
A9: Gary | B9: Bachus | C9: =A9&" "&B9 -> Gary Bachus | D9: 2016 | E9: Des Moines, IA
A10: Don | B10: Bailey | C10: =A10&" "&B10 -> Don Bailey | D10: 2000 | E10: Perry, Iowa 50220 | F10: 1715 Pattee
A11: Tom | B11: Bakey | C11: =A11&" "&B11 -> Tom Bakey | D11: 2003 | E11: Des Moines, IA 50266 | F11: 5605 Cody Drive | J11: 515-457-9515
A12: Dave | B12: Bakey | C12: =A12&" "&B12 -> Dave Bakey | D12: 2021 | E12: Dubuque, IA | F12: 2558 University Avenue | H12: 563-663-7203 | J12: 515-457-9515
A13: Ed | B13: Bartlett (deceased) | C13: =A13&" "&B13 -> Ed Bartlett (deceased) | D13: 1989 | E13: ???, IA ***Deceased***
A14: Kenny | B14: Berg | C14: =A14&" "&B14 -> Kenny Berg | D14: 1993 | E14: Boone, Ia. 50036 ***Deceased*** | F14: 1120 Hancock Dr. #2
A15: Bob | B15: Best (deceased) | C15: =A15&" "&B15 -> Bob Best (deceased) | D15: 1976 | E15: Ames, IA 50010 ***Deceased*** | F15: 1805 Woodhaven Ave | G15: Son - Bob & Kathy Best <bobbest1126@yahoo.com> | J15: 515-232-4911
A16: Wendell | B16: Blankenburg | C16: =A16&" "&B16 -> Wendell Blankenburg | D16: 1987 | E16: Linn Township, IA 50211 | F16: 6426 55 Ave | J16: 515-981-9894
A17: Keith | B17: Boots | C17: =A17&" "&B17 -> Keith Boots | D17: 2019 | E17: Cedar Rapids, IA 52403 | J17: 515-457-9515
A18: Gregg | B18: Bosch | C18: =A18&" "&B18 -> Gregg Bosch | D18: 1995 | E18: Cedar Rapids, Ia. 52405 | F18: 2511 Shawn Court N.W. | G18: gbosch@kirkwood.cc.ia.us
A19: Mel | B19: Bowen (deceased) | C19: =A19&" "&B19 -> Mel Bowen (deceased) | D19: 1978 | E19: Clive, Iowa 50325-8572 | F19: 13261 Cedarwood Ave.
A20: Dodge | B20: Brad | C20: =A20&" "&B20 -> Dodge Brad | D20: 2016 | E20: Sioux City, IA
A21: Bob | B21: Brady | C21: =A21&" "&B21 -> Bob Brady | D21: 2019 | E21: Sioux City, IA | J21: 515-457-9515
A22: Clark | B22: Brollier (deceased) | C22: =A22&" "&B22 -> Clark Brollier (deceased) | D22: 1974 | E22: ???, IA ***Deceased***
A23: Walter | B23: Broussard (deceased) | C23: =A23&" "&B23 -> Walter Broussard (deceased) | D23: 1984 | E23: ???, IA ***Deceased***
A24: Roger | B24: Buddin | C24: =A24&" "&B24 -> Roger Buddin | D24: 1991 | E24: Ollie, IA 52576 | F24: 405 S 2nd St | G24: rrbuddin@yahoo.com | H24: 641-790-1940 | I24: http://bigcountrykennel.com/
A25: Ray | B25: Burlinghame (deceased) | C25: =A25&" "&B25 -> Ray Burlinghame (deceased) | D25: 1973 | E25: ***Deceased***
A26: Paul | B26: Burnett | C26: =A26&" "&B26 -> Paul Burnett | D26: 2000 | E26: Overland Park, Kansas 66213 | F26: 13000 West 125th Street
A27: Tom | B27: Busch (deceased 2006) | C27: =A27&" "&B27 -> Tom Busch (deceased 2006) | D27: 1998 | E27: Cedar Rapids, Ia. 52404 | F27: 1803 2nd Street S.W.
A28: Steve | B28: Calvert | C28: =A28&" "&B28 -> Steve Calvert | D28: 1998 | E28: Cedar Rapids, Ia. 52402-2311 | F28: 2216 Deb Ann Ln. NE
A29: Pete | B29: Canakes | C29: =A29&" "&B29 -> Pete Canakes | D29: 1972 | E29: Boone, IA ***Deceased***
A30: Don | B30: Carlson | C30: =A30&" "&B30 -> Don Carlson | D30: 1972 | E30: Boone, IA / Los Angeles, California 90049 | F30: 825 Norway Lane
A31: LeRoy | B31: Carlson (deceased) | C31: =A31&" "&B31 -> LeRoy Carlson (deceased) | D31: 1983 | E31: Sioux City, Ia. 51104
A32: Al | B32: Carr (deceased) | C32: =A32&" "&B32 -> Al Carr (deceased) | D32: 1985 | E32: Cedar Rapids, IA ***Deceased***
A33: Jim | B33: Caviness (deceased) | C33: =A33&" "&B33 -> Jim Caviness (deceased) | D33: 1984 | E33: Cedar Rapids, Ia. 52405 | F33: 1745 Hillside Drive N.W.
A34: Lawrence | B34: Cheyne (deceased) | C34: =A34&" "&B34 -> Lawrence Cheyne (deceased) | D34: 1983 | E34: Webster City Iowa 50159 ***Deceased***
A35: Gary | B35: Christensen | C35: =A35&" "&B35 -> Gary Christensen | D35: 2001 | E35: Winterset, Iowa | F35: 1704 Patricia Acres
A36: Cory | B36: Christensen | C36: =A36&" "&B36 -> Cory Christensen | D36: 2021 | E36: Raymond, IA 50667-9718 | F36: 550 W Central St
A37: Mike | B37: Christner | C37: =A37&" "&B37 -> Mike Christner | D37: 2015 | E37: Ottumwa, Iowa 52501
A38: Jim | B38: Ciesielski (deceased) | C38: =A38&" "&B38 -> Jim Ciesielski (deceased) | D38: 1993 | E38: Waterloo, IA 50702 | F38: 210 Williston Ave | G38: bigc37c@mchsi.COM | J38: 232-4840
A39: Mike | B39: Clark | C39: =A39&" "&B39 -> Mike Clark | D39: 2021 | E39: Des Moines, IA | F39: 675 46th Street | G39: mclark434@mchsi.com
A40: Bill | B40: Clark (deceased) | C40: =A40&" "&B40 -> Bill Clark (deceased) | D40: 2017 | E40: Sioux City, IA
...

Sheet NameOrder
A1: =General!C1 -> Name | B1: =General!D1 -> Year | C1: =General!F1 -> US Mail Address | D1: =General!E1 -> City / State (played for / living)
A2: =IF(General!C2<>0,General!C2," ") -> Roger Aceto (deceased) | B2: =IF(General!D2<>0,General!D2," ") -> 1982 | C2: =IF(General!F2<>0,General!F2," ") -> 4201 82nd Street | D2: =IF(General!E2<>0,General!E2," ") -> Urbandale Ia. 50322
A3: =IF(General!C4<>0,General!C4," ") -> Ron Amick | B3: =IF(General!D4<>0,General!D4," ") -> 1997 | C3: =IF(General!F4<>0,General!F4," ") -> 1516 Old HWY 141 | D3: =IF(General!E4<>0,General!E4," ") -> Sioux City, Ia. 51106
A4: =IF(General!C7<>0,General!C7," ") -> Ev Andrew (deceased) | B4: =IF(General!D7<>0,General!D7," ") -> 1983 | C4: =IF(General!F7<>0,General!F7," ") | D4: =IF(General!E7<>0,General!E7," ") -> Mount Vernon, IA ***Deceased***
A5: =IF(General!C8<>0,General!C8," ") -> Steve Andrew (deceased) | B5: =IF(General!D8<>0,General!D8," ") -> 1993 | C5: =IF(General!F8<>0,General!F8," ") -> 2180 David Ct. NE | D5: =IF(General!E8<>0,General!E8," ") -> Cedar Rapids, Ia. 52402-2328
A6: =IF(General!C10<>0,General!C10," ") -> Don Bailey | B6: =IF(General!D10<>0,General!D10," ") -> 2000 | C6: =IF(General!F10<>0,General!F10," ") -> 1715 Pattee | D6: =IF(General!E10<>0,General!E10," ") -> Perry, Iowa 50220
A7: =IF(General!C12<>0,General!C12," ") -> Dave Bakey | B7: =IF(General!D12<>0,General!D12," ") -> 2021 | C7: =IF(General!F12<>0,General!F12," ") -> 2558 University Avenue | D7: =IF(General!E12<>0,General!E12," ") -> Dubuque, IA
A8: =IF(General!C13<>0,General!C13," ") -> Ed Bartlett (deceased) | B8: =IF(General!D13<>0,General!D13," ") -> 1989 | C8: =IF(General!F13<>0,General!F13," ") | D8: =IF(General!E13<>0,General!E13," ") -> ???, IA ***Deceased***
A9: =IF(General!C14<>0,General!C14," ") -> Kenny Berg | B9: =IF(General!D14<>0,General!D14," ") -> 1993 | C9: =IF(General!F14<>0,General!F14," ") -> 1120 Hancock Dr. #2 | D9: =IF(General!E14<>0,General!E14," ") -> Boone, Ia. 50036 ***Deceased***
A10: =IF(General!C15<>0,General!C15," ") -> Bob Best (deceased) | B10: =IF(General!D15<>0,General!D15," ") -> 1976 | C10: =IF(General!F15<>0,General!F15," ") -> 1805 Woodhaven Ave | D10: =IF(General!E15<>0,General!E15," ") -> Ames, IA 50010 ***Deceased***
A11: =IF(General!C17<>0,General!C17," ") -> Keith Boots | B11: =IF(General!D17<>0,General!D17," ") -> 2019 | C11: =IF(General!F17<>0,General!F17," ") | D11: =IF(General!E17<>0,General!E17," ") -> Cedar Rapids, IA 52403
A12: =IF(General!C19<>0,General!C19," ") -> Mel Bowen (deceased) | B12: =IF(General!D19<>0,General!D19," ") -> 1978 | C12: =IF(General!F19<>0,General!F19," ") -> 13261 Cedarwood Ave. | D12: =IF(General!E19<>0,General!E19," ") -> Clive, Iowa 50325-8572
A13: =IF(General!C20<>0,General!C20," ") -> Dodge Brad | B13: =IF(General!D20<>0,General!D20," ") -> 2016 | C13: =IF(General!F20<>0,General!F20," ") | D13: =IF(General!E20<>0,General!E20," ") -> Sioux City, IA
A14: =IF(General!C21<>0,General!C21," ") -> Bob Brady | B14: =IF(General!D21<>0,General!D21," ") -> 2019 | C14: =IF(General!F21<>0,General!F21," ") | D14: =IF(General!E21<>0,General!E21," ") -> Sioux City, IA
A15: =IF(General!C23<>0,General!C23," ") -> Walter Broussard (deceased) | B15: =IF(General!D23<>0,General!D23," ") -> 1984 | C15: =IF(General!F23<>0,General!F23," ") | D15: =IF(General!E23<>0,General!E23," ") -> ???, IA ***Deceased***
A16: =IF(General!C24<>0,General!C24," ") -> Roger Buddin | B16: =IF(General!D24<>0,General!D24," ") -> 1991 | C16: =IF(General!F24<>0,General!F24," ") -> 405 S 2nd St | D16: =IF(General!E24<>0,General!E24," ") -> Ollie, IA 52576
A17: =IF(General!C25<>0,General!C25," ") -> Ray Burlinghame (deceased) | B17: =IF(General!D25<>0,General!D25," ") -> 1973 | C17: =IF(General!F25<>0,General!F25," ") | D17: =IF(General!E25<>0,General!E25," ") -> ***Deceased***
A18: =IF(General!C26<>0,General!C26," ") -> Paul Burnett | B18: =IF(General!D26<>0,General!D26," ") -> 2000 | C18: =IF(General!F26<>0,General!F26," ") -> 13000 West 125th Street | D18: =IF(General!E26<>0,General!E26," ") -> Overland Park, Kansas 66213
A19: =IF(General!C27<>0,General!C27," ") -> Tom Busch (deceased 2006) | B19: =IF(General!D27<>0,General!D27," ") -> 1998 | C19: =IF(General!F27<>0,General!F27," ") -> 1803 2nd Street S.W. | D19: =IF(General!E27<>0,General!E27," ") -> Cedar Rapids, Ia. 52404
A20: =IF(General!C28<>0,General!C28," ") -> Steve Calvert | B20: =IF(General!D28<>0,General!D28," ") -> 1998 | C20: =IF(General!F28<>0,General!F28," ") -> 2216 Deb Ann Ln. NE | D20: =IF(General!E28<>0,General!E28," ") -> Cedar Rapids, Ia. 52402-2311
A21: =IF(General!C29<>0,General!C29," ") -> Pete Canakes | B21: =IF(General!D29<>0,General!D29," ") -> 1972 | C21: =IF(General!F29<>0,General!F29," ") | D21: =IF(General!E29<>0,General!E29," ") -> Boone, IA ***Deceased***
A22: =IF(General!C30<>0,General!C30," ") -> Don Carlson | B22: =IF(General!D30<>0,General!D30," ") -> 1972 | C22: =IF(General!F30<>0,General!F30," ") -> 825 Norway Lane | D22: =IF(General!E30<>0,General!E30," ") -> Boone, IA / Los Angeles, California 90049
A23: =IF(General!C31<>0,General!C31," ") -> LeRoy Carlson (deceased) | B23: =IF(General!D31<>0,General!D31," ") -> 1983 | C23: =IF(General!F31<>0,General!F31," ") | D23: =IF(General!E31<>0,General!E31," ") -> Sioux City, Ia. 51104
A24: =IF(General!C32<>0,General!C32," ") -> Al Carr (deceased) | B24: =IF(General!D32<>0,General!D32," ") -> 1985 | C24: =IF(General!F32<>0,General!F32," ") | D24: =IF(General!E32<>0,General!E32," ") -> Cedar Rapids, IA ***Deceased***
A25: =IF(General!C33<>0,General!C33," ") -> Jim Caviness (deceased) | B25: =IF(General!D33<>0,General!D33," ") -> 1984 | C25: =IF(General!F33<>0,General!F33," ") -> 1745 Hillside Drive N.W. | D25: =IF(General!E33<>0,General!E33," ") -> Cedar Rapids, Ia. 52405
A26: =IF(General!C34<>0,General!C34," ") -> Lawrence Cheyne (deceased) | B26: =IF(General!D34<>0,General!D34," ") -> 1983 | C26: =IF(General!F34<>0,General!F34," ") | D26: =IF(General!E34<>0,General!E34," ") -> Webster City Iowa 50159 ***Deceased***
A27: =IF(General!C35<>0,General!C35," ") -> Gary Christensen | B27: =IF(General!D35<>0,General!D35," ") -> 2001 | C27: =IF(General!F35<>0,General!F35," ") -> 1704 Patricia Acres | D27: =IF(General!E35<>0,General!E35," ") -> Winterset, Iowa
A28: =IF(General!C38<>0,General!C38," ") -> Jim Ciesielski (deceased) | B28: =IF(General!D38<>0,General!D38," ") -> 1993 | C28: =IF(General!F38<>0,General!F38," ") -> 210 Williston Ave | D28: =IF(General!E38<>0,General!E38," ") -> Waterloo, IA 50702
A29: =IF(General!C41<>0,General!C41," ") -> Edward Colbert | B29: =IF(General!D41<>0,General!D41," ") -> 1986 | C29: =IF(General!F41<>0,General!F41," ") -> 264 South Grandview | D29: =IF(General!E41<>0,General!E41," ") -> Dubuque, Ia. 52001
A30: =IF(General!C42<>0,General!C42," ") -> Jay Coleman | B30: =IF(General!D42<>0,General!D42," ") -> 2002 | C30: =IF(General!F42<>0,General!F42," ") | D30: =IF(General!E42<>0,General!E42," ") -> Des Moines, IA
A31: =IF(General!C43<>0,General!C43," ") -> Sam Cordaro (deceased) | B31: =IF(General!D43<>0,General!D43," ") -> 1975 | C31: =IF(General!F43<>0,General!F43," ") | D31: =IF(General!E43<>0,General!E43," ") -> ???, IA ***Deceased***
A32: =IF(General!C46<>0,General!C46," ") -> Rick Daniels | B32: =IF(General!D46<>0,General!D46," ") -> 2021 | C32: =IF(General!F46<>0,General!F46," ") | D32: =IF(General!E46<>0,General!E46," ") -> Cedar Rapids
A33: =IF(General!C47<>0,General!C47," ") -> Don Dannen (deceased) | B33: =IF(General!D47<>0,General!D47," ") -> 1993 | C33: =IF(General!F47<>0,General!F47," ") | D33: =IF(General!E47<>0,General!E47," ") -> Phoenix, AZ ***Deceased***
A34: =IF(General!C50<>0,General!C50," ") -> Nyall Davis (deceased) | B34: =IF(General!D50<>0,General!D50," ") -> 1973 | C34: =IF(General!F50<>0,General!F50," ") | D34: =IF(General!E50<>0,General!E50," ") -> ???, IA ***Deceased***
A35: =IF(General!C51<>0,General!C51," ") -> Abie Davis (deceased) | B35: =IF(General!D51<>0,General!D51," ") -> 2022 | C35: =IF(General!F51<>0,General!F51," ") | D35: =IF(General!E51<>0,General!E51," ") -> Sully, IA
A36: =IF(General!C52<>0,General!C52," ") -> Don Deberg | B36: =IF(General!D52<>0,General!D52," ") -> 1985 | C36: =IF(General!F52<>0,General!F52," ") -> 3931 Scenic Drive | D36: =IF(General!E52<>0,General!E52," ") -> Waterloo, Ia. 50701
A37: =IF(General!C54<>0,General!C54," ") -> Denny Delorit | B37: =IF(General!D54<>0,General!D54," ") -> 2015 | C37: =IF(General!F54<>0,General!F54," ") | D37: =IF(General!E54<>0,General!E54," ") -> Sioux City, IA
A38: =IF(General!C57<>0,General!C57," ") -> Lance Dreesman | B38: =IF(General!D57<>0,General!D57," ") -> 1991 | C38: =IF(General!F57<>0,General!F57," ") -> 1623 Reed Street | D38: =IF(General!E57<>0,General!E57," ") -> Grinnell Ia. 50012
A39: =IF(General!C58<>0,General!C58," ") -> Bill Driscoll | B39: =IF(General!D58<>0,General!D58," ") -> 1980 | C39: =IF(General!F58<>0,General!F58," ") -> 936 Owen Street N.W. | D39: =IF(General!E58<>0,General!E58," ") -> Cedar Rapids, Ia. 52405
A40: =IF(General!C60<>0,General!C60," ") -> Lou Dvorak (deceased) | B40: =IF(General!D60<>0,General!D60," ") -> 1976 | C40: =IF(General!F60<>0,General!F60," ") | D40: =IF(General!E60<>0,General!E60," ") -> ???, IA ***Deceased***
...
