Workbook

Sheet Iowa Men's Fastpitch Summary
A1: 2026 - Iowa Men's Fastpitch Hall of Fame Induction Voting Summary
A2: 46113
C3: ='RAW Data'!C4 -> Jack Arendt | D3: ='RAW Data'!D4 -> Gordy Baker
A4: Members Voting ------------------> | B4: =ROWS('RAW Data'!A5:A54) -> 50 | C4: =COUNTIF('RAW Data'!C$5:C$54, "Yes") -> 22 | D4: =COUNTIF('RAW Data'!D$5:D$54, "Yes") -> 19 | E4: <- Yes
A5: Percent Needed To Induct -------> | B5: 0.75 | C5: =COUNTIF('RAW Data'!C$5:C$54, "No") -> 9 | D5: =COUNTIF('RAW Data'!D$5:D$54, "No") -> 3 | E5: <- No
A6: Number of Required Responses-> | B6: =ROUND(B4/2,0) -> 25 | C6: =COUNTIF('RAW Data'!C$5:C$54, "No Opinion") -> 19 | D6: =COUNTIF('RAW Data'!D$5:D$54, "No Opinion") -> 28 | E6: <- No Opinion
C7: =C4/(C4+C5) -> 0.70967742 | D7: =D4/(D4+D5) -> 0.86363636 | E7: <- Percent "Yes"
C9: ='RAW Data'!E4 -> Brian Nelson | D9: ='RAW Data'!F4 -> Dave Donahue
C10: =COUNTIF('RAW Data'!E$5:E$54, "Yes") -> 6 | D10: =COUNTIF('RAW Data'!F$5:F$54, "Yes") -> 18 | E10: =E4 -> <- Yes
C11: =COUNTIF('RAW Data'!E$5:E$54, "No") -> 11 | D11: =COUNTIF('RAW Data'!F$5:F$54, "No") -> 5 | E11: =E5 -> <- No
C12: =COUNTIF('RAW Data'!E$5:E$54, "No Opinion") -> 33 | D12: =COUNTIF('RAW Data'!F$5:F$54, "No Opinion") -> 27 | E12: =E6 -> <- No Opinion
C13: =C10/(C10+C11) -> 0.35294118 | D13: =D10/(D10+D11) -> 0.7826087 | E13: =E7 -> <- Percent "Yes"
C15: ='RAW Data'!G4 -> Russ Hutchinson | D15: ='RAW Data'!H4 -> Greg Mara
C16: =COUNTIF('RAW Data'!G$5:G$54, "Yes") -> 17 | D16: =COUNTIF('RAW Data'!H$5:H$54, "Yes") -> 20 | E16: =E10 -> <- Yes
C17: =COUNTIF('RAW Data'!G$5:G$54, "No") -> 10 | D17: =COUNTIF('RAW Data'!H$5:H$54, "No") -> 9 | E17: =E11 -> <- No
C18: =COUNTIF('RAW Data'!G$5:G$54, "No Opinion") -> 23 | D18: =COUNTIF('RAW Data'!H$5:H$54, "No Opinion") -> 21 | E18: =E12 -> <- No Opinion
C19: =C16/(C16+C17) -> 0.62962963 | D19: =D16/(D16+D17) -> 0.68965517 | E19: =E13 -> <- Percent "Yes"
C21: ='RAW Data'!I4 -> Scott O'Brien | D21: ='RAW Data'!J4 -> Jim O'Hern
C22: =COUNTIF('RAW Data'!I$5:I$54, "Yes") -> 13 | D22: =COUNTIF('RAW Data'!J$5:J$54, "Yes") -> 13 | E22: =E16 -> <- Yes
C23: =COUNTIF('RAW Data'!I$5:I$54, "No") -> 9 | D23: =COUNTIF('RAW Data'!J$5:J$54, "No") -> 7 | E23: =E17 -> <- No
C24: =COUNTIF('RAW Data'!I$5:I$54, "No Opinion") -> 28 | D24: =COUNTIF('RAW Data'!J$5:J$54, "No Opinion") -> 30 | E24: =E18 -> <- No Opinion
C25: =C22/(C22+C23) -> 0.59090909 | D25: =D22/(D22+D23) -> 0.65 | E25: =E19 -> <- Percent "Yes"
C27: ='RAW Data'!K4 -> John "JR" Ogden | D27: ='RAW Data'!L4 -> Matt Palazzo
C28: =COUNTIF('RAW Data'!K$5:K$54, "Yes") -> 28 | D28: =COUNTIF('RAW Data'!L$5:L$54, "Yes") -> 31 | E28: =E22 -> <- Yes
C29: =COUNTIF('RAW Data'!K$5:K$54, "No") -> 3 | D29: =COUNTIF('RAW Data'!L$5:L$54, "No") -> 1 | E29: =E23 -> <- No
C30: =COUNTIF('RAW Data'!K$5:K$54, "No Opinion") -> 19 | D30: =COUNTIF('RAW Data'!L$5:L$54, "No Opinion") -> 18 | E30: =E24 -> <- No Opinion
C31: =C28/(C28+C29) -> 0.90322581 | D31: =D28/(D28+D29) -> 0.96875 | E31: =E25 -> <- Percent "Yes"
C33: ='RAW Data'!M4 -> Scott Smith | D33: ='RAW Data'!N4 -> Zack Smith
C34: =COUNTIF('RAW Data'!M$5:M$54, "Yes") -> 30 | D34: =COUNTIF('RAW Data'!N$5:N$54, "Yes") -> 3 | E34: =E28 -> <- Yes
C35: =COUNTIF('RAW Data'!M$5:M$54, "No") -> 3 | D35: =COUNTIF('RAW Data'!N$5:N$54, "No") -> 13 | E35: =E29 -> <- No
C36: =COUNTIF('RAW Data'!M$5:M$54, "No Opinion") -> 17 | D36: =COUNTIF('RAW Data'!N$5:N$54, "No Opinion") -> 34 | E36: =E30 -> <- No Opinion
C37: =C34/(C34+C35) -> 0.90909091 | D37: =D34/(D34+D35) -> 0.1875 | E37: =E31 -> <- Percent "Yes"
C39: ='RAW Data'!O4 -> Bob Splinter II | D39: ='RAW Data'!P4 -> Larry Svoboda
C40: =COUNTIF('RAW Data'!O$5:O$54, "Yes") -> 12 | D40: =COUNTIF('RAW Data'!P$5:P$54, "Yes") -> 16 | E40: =E34 -> <- Yes
C41: =COUNTIF('RAW Data'!O$5:O$54, "No") -> 9 | D41: =COUNTIF('RAW Data'!P$5:P$54, "No") -> 3 | E41: =E35 -> <- No
C42: =COUNTIF('RAW Data'!O$5:O$54, "No Opinion") -> 29 | D42: =COUNTIF('RAW Data'!P$5:P$54, "No Opinion") -> 31 | E42: =E36 -> <- No Opinion
C43: =C40/(C40+C41) -> 0.57142857 | D43: =D40/(D40+D41) -> 0.84210526 | E43: =E37 -> <- Percent "Yes"
C46: ='RAW Data'!Q4 -> Brad Wedeking | D46: ='RAW Data'!R4 -> Charles Stufflebeem Sr. | E46: =E40 -> <- Yes
C47: =COUNTIF('RAW Data'!Q$5:Q$54, "Yes") -> 27 | D47: =COUNTIF('RAW Data'!R$5:R$54, "Yes") -> 16 | E47: =E41 -> <- No
C48: =COUNTIF('RAW Data'!Q$5:Q$54, "No") -> 5 | D48: =COUNTIF('RAW Data'!R$5:R$54, "No") -> 5 | E48: =E42 -> <- No Opinion
...

Sheet RAW Data
A1: 2026 - Iowa Men's Fastpitch Hall of Fame Induction Voting RAW Data
A2: ='Iowa Men''s Fastpitch Summary'!A2 -> 46113
C3: Name ------>>
A4: Timestamp of Vote | B4: Votes by | C4: Jack Arendt | D4: Gordy Baker | E4: Brian Nelson | F4: Dave Donahue | G4: Russ Hutchinson | H4: Greg Mara | I4: Scott O'Brien | J4: Jim O'Hern | K4: John "JR" Ogden | L4: Matt Palazzo | M4: Scott Smith | N4: Zack Smith | O4: Bob Splinter II | P4: Larry Svoboda | Q4: Brad Wedeking | R4: Charles Stufflebeem Sr. | S4: Yes | T4: No | U4: No Opinion
A5: 2026/03/15 8:34:03 AM EST | B5: stevekaiser020@gmail.com | C5: Yes | D5: No Opinion | E5: No Opinion | F5: No Opinion | G5: No Opinion | H5: No Opinion | I5: No Opinion | J5: No Opinion | K5: No Opinion | L5: Yes | M5: No Opinion | N5: No Opinion | O5: No | P5: No Opinion | Q5: No Opinion | R5: No Opinion | S5: =COUNTIF(C5:R5, "Yes") -> 2 | T5: =COUNTIF(C5:R5, "No") -> 1 | U5: =COUNTIF(C5:R5, "No Opinion") -> 13 | W5: stevekaiser020@gmail.com
A6: 2026/03/15 8:39:48 AM EST | B6: dmw52581@gmail.com | C6: No Opinion | D6: Yes | E6: No Opinion | F6: Yes | G6: Yes | H6: Yes | I6: No Opinion | J6: No Opinion | K6: No Opinion | L6: Yes | M6: Yes | N6: No Opinion | O6: No Opinion | P6: No Opinion | Q6: Yes | R6: Yes | S6: =COUNTIF(C6:R6, "Yes") -> 8 | T6: =COUNTIF(C6:R6, "No") -> 0 | U6: =COUNTIF(C6:R6, "No Opinion") -> 8 | W6: dmw52581@gmail.com
A7: 2026/03/15 9:05:18 AM EST | B7: towen@iowatelecom.net | C7: No Opinion | D7: No Opinion | E7: No Opinion | F7: No | G7: Yes | H7: No Opinion | I7: Yes | J7: No Opinion | K7: No Opinion | L7: Yes | M7: Yes | N7: No Opinion | O7: No Opinion | P7: No Opinion | Q7: No | R7: No Opinion | S7: =COUNTIF(C7:R7, "Yes") -> 4 | T7: =COUNTIF(C7:R7, "No") -> 2 | U7: =COUNTIF(C7:R7, "No Opinion") -> 10 | W7: towen@iowatelecom.net
A8: 2026/03/15 9:14:38 AM EST | B8: steve.vanginkel@sterling.com | C8: No Opinion | D8: No Opinion | E8: No Opinion | F8: No Opinion | G8: No Opinion | H8: No Opinion | I8: Yes | J8: Yes | K8: No Opinion | L8: No Opinion | M8: Yes | N8: No Opinion | O8: No Opinion | P8: Yes | Q8: No Opinion | R8: No Opinion | S8: =COUNTIF(C8:R8, "Yes") -> 4 | T8: =COUNTIF(C8:R8, "No") -> 0 | U8: =COUNTIF(C8:R8, "No Opinion") -> 12 | W8: steve.vanginkel@sterling.com
A9: 2026/03/15 9:35:01 AM EST | B9: leroyweg@outlook.com | C9: No | D9: No | E9: No | F9: Yes | G9: No | H9: Yes | I9: No | J9: No | K9: Yes | L9: Yes | M9: Yes | N9: No | O9: Yes | P9: Yes | Q9: Yes | R9: No | S9: =COUNTIF(C9:R9, "Yes") -> 8 | T9: =COUNTIF(C9:R9, "No") -> 8 | U9: =COUNTIF(C9:R9, "No Opinion") -> 0 | W9: leroyweg@outlook.com
A10: 2026/03/15 9:40:27 AM EST | B10: seveboy@aol.com | C10: No Opinion | D10: No Opinion | E10: Yes | F10: No Opinion | G10: No Opinion | H10: No Opinion | I10: No Opinion | J10: No Opinion | K10: No Opinion | L10: No Opinion | M10: Yes | N10: No Opinion | O10: No Opinion | P10: No Opinion | Q10: No Opinion | R10: No Opinion | S10: =COUNTIF(C10:R10, "Yes") -> 2 | T10: =COUNTIF(C10:R10, "No") -> 0 | U10: =COUNTIF(C10:R10, "No Opinion") -> 14 | W10: seveboy@aol.com
A11: 2026/03/15 10:11:03 AM EST | B11: garyhasky@aol.com | C11: No | D11: Yes | E11: No Opinion | F11: No Opinion | G11: Yes | H11: No | I11: No Opinion | J11: No Opinion | K11: Yes | L11: No Opinion | M11: Yes | N11: No Opinion | O11: No | P11: No Opinion | Q11: Yes | R11: Yes | S11: =COUNTIF(C11:R11, "Yes") -> 6 | T11: =COUNTIF(C11:R11, "No") -> 3 | U11: =COUNTIF(C11:R11, "No Opinion") -> 7 | W11: garyhasky@aol.com
A12: 2026/03/15 10:43:15 AM EST | B12: minordean5@gmail.com | C12: Yes | D12: Yes | E12: Yes | F12: Yes | G12: Yes | H12: Yes | I12: Yes | J12: Yes | K12: Yes | L12: Yes | M12: Yes | N12: Yes | O12: Yes | P12: Yes | Q12: Yes | R12: Yes | S12: =COUNTIF(C12:R12, "Yes") -> 16 | T12: =COUNTIF(C12:R12, "No") -> 0 | U12: =COUNTIF(C12:R12, "No Opinion") -> 0 | V12: Yes | W12: minordean5@gmail.com
A13: 2026/03/15 10:57:56 AM EST | B13: chuckwelker@aol.com | C13: No | D13: Yes | E13: No | F13: No | G13: No | H13: No | I13: No Opinion | J13: No | K13: No | L13: Yes | M13: No | N13: No | O13: No | P13: Yes | Q13: No | R13: No | S13: =COUNTIF(C13:R13, "Yes") -> 3 | T13: =COUNTIF(C13:R13, "No") -> 12 | U13: =COUNTIF(C13:R13, "No Opinion") -> 1 | W13: chuckwelker@aol.com
A14: 2026/03/15 11:15:55 AM EST | B14: jay.coleman@mchsi.com | C14: Yes | D14: No Opinion | E14: No Opinion | F14: No Opinion | G14: No Opinion | H14: No Opinion | I14: No Opinion | J14: No Opinion | K14: Yes | L14: No Opinion | M14: Yes | N14: No Opinion | O14: No Opinion | P14: No Opinion | Q14: No Opinion | R14: No Opinion | S14: =COUNTIF(C14:R14, "Yes") -> 3 | T14: =COUNTIF(C14:R14, "No") -> 0 | U14: =COUNTIF(C14:R14, "No Opinion") -> 13 | W14: jay.coleman@mchsi.com
A15: 2026/03/15 12:47:07 PM EST | B15: arausch@netins.net | C15: Yes | D15: Yes | E15: No | F15: Yes | G15: No Opinion | H15: No | I15: No | J15: No Opinion | K15: Yes | L15: Yes | M15: Yes | N15: No | O15: No Opinion | P15: Yes | Q15: Yes | R15: No Opinion | S15: =COUNTIF(C15:R15, "Yes") -> 8 | T15: =COUNTIF(C15:R15, "No") -> 4 | U15: =COUNTIF(C15:R15, "No Opinion") -> 4 | W15: arausch@netins.net
A16: 2026/03/15 3:38:41 PM EST | B16: gchristensen@centurylink.net | C16: No Opinion | D16: Yes | E16: No Opinion | F16: Yes | G16: No | H16: No Opinion | I16: Yes | J16: No Opinion | K16: No Opinion | L16: Yes | M16: Yes | N16: No Opinion | O16: No Opinion | P16: No Opinion | Q16: Yes | R16: No Opinion | S16: =COUNTIF(C16:R16, "Yes") -> 6 | T16: =COUNTIF(C16:R16, "No") -> 1 | U16: =COUNTIF(C16:R16, "No Opinion") -> 9 | W16: gchristensen@centurylink.net
A17: 2026/03/15 10:14:40 PM EST | B17: bobfontana77@gmail.com | C17: No | D17: No Opinion | E17: No Opinion | F17: Yes | G17: Yes | H17: Yes | I17: No Opinion | J17: No Opinion | K17: No Opinion | L17: Yes | M17: Yes | N17: No | O17: No Opinion | P17: No Opinion | Q17: Yes | R17: No Opinion | S17: =COUNTIF(C17:R17, "Yes") -> 6 | T17: =COUNTIF(C17:R17, "No") -> 2 | U17: =COUNTIF(C17:R17, "No Opinion") -> 8 | W17: bobfontana77@gmail.com
A18: 2026/03/16 10:12:32 AM EST | B18: mbtranel77@gmail.com | C18: Yes | D18: No Opinion | E18: No Opinion | F18: Yes | G18: Yes | H18: Yes | I18: No Opinion | J18: No Opinion | K18: Yes | L18: No Opinion | M18: No Opinion | N18: No Opinion | O18: Yes | P18: No Opinion | Q18: Yes | R18: Yes | S18: =COUNTIF(C18:R18, "Yes") -> 8 | T18: =COUNTIF(C18:R18, "No") -> 0 | U18: =COUNTIF(C18:R18, "No Opinion") -> 8 | W18: mbtranel77@gmail.com
A19: 2026/03/16 10:30:57 AM EST | B19: hartzellr53@uiu.edu | C19: No | D19: No Opinion | E19: No Opinion | F19: No Opinion | G19: No Opinion | H19: Yes | I19: No Opinion | J19: No Opinion | K19: Yes | L19: No Opinion | M19: No Opinion | N19: No Opinion | O19: No Opinion | P19: Yes | Q19: No Opinion | R19: No Opinion | S19: =COUNTIF(C19:R19, "Yes") -> 3 | T19: =COUNTIF(C19:R19, "No") -> 1 | U19: =COUNTIF(C19:R19, "No Opinion") -> 12 | W19: hartzellr53@uiu.edu
A20: 2026/03/16 11:15:26 AM EST | B20: layacinich@grandview.edu | C20: Yes | D20: No Opinion | E20: No Opinion | F20: Yes | G20: No Opinion | H20: No Opinion | I20: No Opinion | J20: Yes | K20: No Opinion | L20: Yes | M20: Yes | N20: No Opinion | O20: No Opinion | P20: No Opinion | Q20: No Opinion | R20: No Opinion | S20: =COUNTIF(C20:R20, "Yes") -> 5 | T20: =COUNTIF(C20:R20, "No") -> 0 | U20: =COUNTIF(C20:R20, "No Opinion") -> 11 | W20: layacinich@grandview.edu
A21: 2026/03/16 12:08:15 PM EST | B21: almllyvandyke@iowatelecom.net | C21: Yes | D21: Yes | E21: Yes | F21: Yes | G21: Yes | H21: Yes | I21: No | J21: Yes | K21: No | L21: Yes | M21: No Opinion | N21: No Opinion | O21: Yes | P21: Yes | Q21: Yes | R21: Yes | S21: =COUNTIF(C21:R21, "Yes") -> 12 | T21: =COUNTIF(C21:R21, "No") -> 2 | U21: =COUNTIF(C21:R21, "No Opinion") -> 2 | W21: almllyvandyke@iowatelecom.net
A22: 2026/03/16 12:29:49 PM EST | B22: tom.peterson@uni.edu | C22: Yes | D22: Yes | E22: No | F22: No Opinion | G22: No | H22: No | I22: No | J22: No Opinion | K22: Yes | L22: Yes | M22: No Opinion | N22: No | O22: Yes | P22: Yes | Q22: Yes | R22: No Opinion | S22: =COUNTIF(C22:R22, "Yes") -> 7 | T22: =COUNTIF(C22:R22, "No") -> 5 | U22: =COUNTIF(C22:R22, "No Opinion") -> 4 | W22: tom.peterson@uni.edu
A23: 2026/03/16 12:35:33 PM EST | B23: howieprotivin@gmail.com | C23: No Opinion | D23: No Opinion | E23: No | F23: No Opinion | G23: Yes | H23: Yes | I23: No Opinion | J23: Yes | K23: Yes | L23: Yes | M23: No Opinion | N23: No Opinion | O23: Yes | P23: Yes | Q23: Yes | R23: Yes | S23: =COUNTIF(C23:R23, "Yes") -> 9 | T23: =COUNTIF(C23:R23, "No") -> 1 | U23: =COUNTIF(C23:R23, "No Opinion") -> 6 | W23: howieprotivin@gmail.com
A24: 2026/03/16 1:52:26 PM EST | B24: ynot.nelson@pm.me | C24: No Opinion | D24: Yes | E24: No Opinion | F24: Yes | G24: Yes | H24: No Opinion | I24: Yes | J24: No Opinion | K24: No Opinion | L24: Yes | M24: Yes | N24: No Opinion | O24: No Opinion | P24: No Opinion | Q24: Yes | R24: No Opinion | S24: =COUNTIF(C24:R24, "Yes") -> 7 | T24: =COUNTIF(C24:R24, "No") -> 0 | U24: =COUNTIF(C24:R24, "No Opinion") -> 9 | W24: ynot.nelson@pm.me
... A54: 2026/03/31 4:31:32 PM EST | B54: sapeot@msn.com | C54: Yes | D54: Yes | E54: No Opinion | F54: Yes | G54: Yes | H54: Yes | I54: No Opinion | J54: Yes | K54: Yes | L54: Yes | M54: Yes | N54: No Opinion | O54: Yes | P54: Yes | Q54: Yes | R54: Yes | S54: =COUNTIF(C54:R54, "Yes") -> 13 | T54: =COUNTIF(C54:R54, "No") -> 0 | U54: =COUNTIF(C54:R54, "No Opinion") -> 3 | W54: sapeot@msn.com
C55: =C4 -> Jack Arendt | D55: =D4 -> Gordy Baker | E55: =E4 -> Brian Nelson | F55: =F4 -> Dave Donahue | G55: =G4 -> Russ Hutchinson | H55: =H4 -> Greg Mara | I55: =I4 -> Scott O'Brien | J55: =J4 -> Jim O'Hern | ... R55: =R4 -> Charles Stufflebeem Sr. | S55: Yes | T55: No | U55: No Opinion
B56: Yes ------------------------------------>> | C56: =COUNTIF(C5:C54, "Yes") -> 22 | D56: =COUNTIF(D5:D54, "Yes") -> 19 | E56: =COUNTIF(E5:E54, "Yes") -> 6 | F56: =COUNTIF(F5:F54, "Yes") -> 18 | G56: =COUNTIF(G5:G54, "Yes") -> 17 | H56: =COUNTIF(H5:H54, "Yes") -> 20 | I56: =COUNTIF(I5:I54, "Yes") -> 13 | J56: =COUNTIF(J5:J54, "Yes") -> 13 | ... R56: =COUNTIF(R5:R54, "Yes") -> 16
B57: No ------------------------------------>> | C57: =COUNTIF(C6:C55, "No") -> 9 | D57: =COUNTIF(D6:D55, "No") -> 3 | E57: =COUNTIF(E6:E55, "No") -> 11 | F57: =COUNTIF(F6:F55, "No") -> 5 | G57: =COUNTIF(G6:G55, "No") -> 10 | H57: =COUNTIF(H6:H55, "No") -> 9 | I57: =COUNTIF(I6:I55, "No") -> 9 | J57: =COUNTIF(J6:J55, "No") -> 7 | ... R57: =COUNTIF(R6:R55, "No") -> 5
B58: No Opinion ------------------------->> | C58: =COUNTIF(C7:C56, "No Opinion") -> 18 | D58: =COUNTIF(D7:D56, "No Opinion") -> 27 | E58: =COUNTIF(E7:E56, "No Opinion") -> 31 | F58: =COUNTIF(F7:F56, "No Opinion") -> 26 | G58: =COUNTIF(G7:G56, "No Opinion") -> 22 | H58: =COUNTIF(H7:H56, "No Opinion") -> 20 | I58: =COUNTIF(I7:I56, "No Opinion") -> 26 | J58: =COUNTIF(J7:J56, "No Opinion") -> 28 | ... R58: =COUNTIF(R7:R56, "No Opinion") -> 28
S59: =SUM(S5:S55) -> 291 | T59: =SUM(T5:T55) -> 105 | U59: =SUM(U5:U55) -> 404 | W59: =S59/55 -> 5.2909091
A62: 46096.447 | B62: minordean5@gmail.com | C62: Yes | D62: Yes | E62: Yes | F62: Yes | G62: Yes | H62: Yes | I62: Yes | J62: Yes | K62: Yes | L62: Yes | M62: Yes | N62: Yes | O62: Yes | P62: Yes | Q62: Yes | R62: Yes | S62: Yes | T62: Yes | U62: Yes | V62: Yes
